scripts/tests/1.in
5
o
2 S 0 8 7613 80
4 B 1 0 4303 78
2 S 2 3 6611 59
1 B 3 2 8275 23
2 B 4 7 3338 44
3 S 5 0 1691 28
1 C 3
1 S 6 3 8046 83
4 C 1
3 S 7 6 2724 97
1 B 8 2 2794 12
1 C 8
1 S 9 4 7350 80
2 C 2
0 S 10 3 8513 46
3 B 11 5 1918 96
1 B 12 2 5863 36
2 C 0
4 C 1
3 S 13 0 5991 28
2 S 14 2 5005 55
3 S 15 4 9707 51
0 S 16 5 7615 31
3 S 17 3 2438 65
4 B 18 6 4064 1
0 S 19 7 3899 70
0 C 10
2 B 20 0 178 58
3 S 21 0 7618 55
3 S 22 1 3588 12
0 C 10
3 C 7
4 C 1
4 C 18
3 C 15
2 B 23 4 2066 59
2 S 24 3 6646 96
1 S 25 2 4224 85
0 B 26 0 3859 92
0 S 27 0 8393 7
2 B 28 4 7706 58
0 C 16
1 S 29 6 9960 20
4 S 30 1 3577 5
2 B 31 9 52 42
3 S 32 4 1224 75
3 C 32
3 B 33 0 730 29
2 S 34 9 6533 10
3 B 35 6 6688 42
3 B 36 7 8917 25
1 C 12
2 B 37 8 6819 77
0 S 38 0 5175 14
3 S 39 2 1847 22
1 B 40 5 2346 9
1 B 41 3 3089 48
0 B 42 8 2467 4
0 B 43 2 9333 19
3 B 44 5 6831 11
2 B 45 3 6456 61
2 B 46 5 675 65
3 S 47 8 6493 98
3 C 36
1 C 3
0 S 48 0 5582 67
1 S 49 4 6432 19
3 C 17
3 S 50 0 3173 64
4 B 51 7 7168 31
4 B 52 5 5279 97
2 S 53 8 5781 33
3 S 54 6 4012 10
0 C 27
0 S 55 6 8321 87
2 S 56 8 9992 65
3 S 57 8 2324 61
0 B 58 3 613 10
0 C 16
2 C 28
2 S 59 7 7552 12
1 S 60 2 6370 99
2 B 61 7 1463 73
1 S 62 1 3583 42
2 S 63 7 8989 44
3 C 39
4 B 64 0 5985 57
1 C 60
3 B 65 3 9989 29
0 S 66 4 8574 47
1 B 67 0 3009 12
2 S 68 7 4777 38
1 B 69 1 1182 36
1 B 70 7 2833 53
1 B 71 2 8373 75
4 C 52
4 C 30
.
x
