scripts/tests/2.in
10
o
0 B 0 48 249 67
5 S 1 43 5859 2
6 B 2 47 9891 46
3 S 3 8 8831 83
0 S 4 30 2618 55
9 B 5 15 2493 55
0 S 6 35 4322 33
7 B 7 26 6750 80
9 B 8 23 8254 93
6 B 9 2 6611 21
9 C 5
4 S 10 34 2147 27
9 C 5
1 S 11 44 2739 70
8 B 12 6 9397 48
7 S 13 26 6100 53
9 C 8
5 B 14 29 5277 8
8 B 15 27 3405 62
8 B 16 47 6891 81
4 B 17 29 9799 31
4 S 18 15 1856 97
9 S 19 21 5591 8
9 S 20 32 1219 62
6 C 2
2 S 21 16 7970 94
3 S 22 43 496 69
2 S 23 46 8059 64
5 C 14
3 S 24 3 8601 84
4 B 25 47 9238 93
2 S 26 48 2066 65
1 B 27 0 8152 5
8 S 28 49 7960 46
1 B 29 37 4266 19
6 B 30 32 8131 29
6 B 31 39 511 29
8 S 32 11 1667 8
2 S 33 38 1164 21
9 C 19
4 C 17
6 S 34 17 5551 12
2 B 35 9 8052 93
8 B 36 20 9575 77
1 C 27
4 S 37 21 7423 92
9 B 38 21 3942 66
3 B 39 5 3949 51
0 C 4
6 C 34
8 C 12
1 S 40 10 4344 18
3 B 41 47 1228 66
3 C 39
5 B 42 20 9244 75
2 S 43 38 4511 27
0 S 44 6 9460 57
5 B 45 17 4863 70
7 B 46 44 9253 3
9 S 47 17 6393 15
4 S 48 3 1696 93
2 B 49 34 3907 87
1 C 27
0 B 50 11 3932 5
0 C 50
7 B 51 49 6836 5
7 B 52 9 4234 47
7 C 13
5 C 42
6 C 9
4 B 53 34 2434 77
5 B 54 33 4119 20
4 C 18
1 B 55 46 7326 25
1 B 56 21 7400 79
2 C 35
4 C 48
5 S 57 15 1992 76
3 S 58 42 2330 52
8 S 59 11 668 34
6 B 60 6 6225 97
5 B 61 31 1646 82
7 S 62 9 976 18
8 C 28
0 B 63 33 6153 5
8 C 28
8 C 16
7 S 64 12 9917 6
5 B 65 17 6027 31
0 S 66 12 5535 3
0 B 67 26 6789 45
4 B 68 22 9126 68
5 B 69 35 4126 28
2 S 70 9 5647 57
8 S 71 42 80 28
6 S 72 15 5325 44
7 S 73 11 5098 43
6 S 74 8 8631 25
1 C 40
1 B 75 12 4244 31
6 B 76 12 712 97
8 C 28
2 S 77 35 7977 6
6 S 78 1 8600 58
1 B 79 48 9593 18
3 C 24
3 B 80 45 4978 38
6 B 81 7 7302 40
9 B 82 45 8702 11
4 S 83 44 6046 26
1 S 84 46 8951 41
1 C 40
9 B 85 42 181 60
6 B 86 40 6594 2
4 S 87 44 8942 28
0 C 4
7 B 88 12 6138 62
9 B 89 5 2014 91
4 S 90 37 2015 90
4 C 48
2 C 43
6 B 91 25 5884 12
3 B 92 18 3535 61
2 S 93 15 5157 81
0 C 4
0 B 94 29 3971 84
5 C 14
8 C 59
7 C 46
5 C 61
9 C 82
0 B 95 33 8030 67
2 C 26
8 B 96 12 7100 44
9 S 97 27 3023 38
1 S 98 4 4146 40
9 C 97
1 S 99 5 2795 42
4 S 100 5 7389 62
8 C 96
1 S 101 3 143 46
5 S 102 11 8201 76
6 B 103 20 8255 26
0 S 104 4 7276 25
9 S 105 31 8174 51
5 S 106 38 4134 99
3 C 39
7 B 107 28 3815 78
9 S 108 30 5429 82
5 S 109 21 8372 30
9 B 110 39 7203 23
7 B 111 29 9026 44
1 B 112 34 8070 70
4 B 113 27 2387 20
1 S 114 2 857 35
6 B 115 21 4009 11
6 S 116 29 3494 70
5 B 117 5 5537 60
9 C 19
4 C 83
1 B 118 19 7440 92
2 S 119 5 1745 74
3 B 120 8 5142 96
6 C 116
6 C 2
8 S 121 32 7688 30
6 S 122 32 9248 5
1 C 75
6 C 2
2 C 21
2 B 123 41 6783 26
5 S 124 44 3171 23
2 S 125 1 4551 9
9 B 126 9 1810 62
9 S 127 29 6384 56
8 C 12
4 C 17
0 C 94
0 S 128 39 7611 89
2 B 129 4 1688 14
6 B 130 37 8401 71
4 S 131 7 1227 91
2 C 93
4 B 132 32 5068 9
8 S 133 3 4036 67
9 C 127
9 C 89
2 B 134 16 9593 46
6 C 2
2 C 123
4 C 131
6 S 135 39 4301 87
8 C 15
4 S 136 0 3761 41
4 S 137 34 7633 79
8 C 32
2 S 138 22 9873 99
8 S 139 13 5206 98
6 B 140 26 6407 9
7 C 107
7 C 51
7 B 141 32 2747 92
2 B 142 27 4872 70
3 B 143 19 9873 73
0 C 104
8 C 71
0 C 67
8 C 139
4 C 132
6 C 74
1 S 144 39 134 46
0 S 145 33 6804 97
9 C 108
5 S 146 46 6615 67
0 S 147 40 6958 66
6 B 148 33 4921 80
8 S 149 13 5095 61
9 B 150 27 7602 76
2 S 151 33 7935 55
1 S 152 43 8728 51
9 S 153 20 9035 41
2 C 35
1 C 29
6 B 154 46 9677 88
4 B 155 41 5648 6
3 B 156 15 5624 60
2 S 157 7 2164 61
4 B 158 7 8232 55
7 C 107
1 C 55
5 C 117
6 C 2
9 B 159 1 6349 5
6 B 160 2 2350 53
2 S 161 16 2849 63
9 B 162 39 417 36
8 B 163 26 4061 96
6 B 164 47 6305 52
5 S 165 46 532 73
2 S 166 36 3688 98
7 S 167 35 1164 66
5 C 124
3 C 41
7 B 168 49 5626 78
1 B 169 49 6838 55
0 B 170 25 2087 19
3 S 171 26 4955 81
2 C 161
6 B 172 30 194 84
2 B 173 8 7556 99
4 B 174 14 2271 49
3 S 175 36 1235 70
7 C 88
8 B 176 14 2902 6
2 S 177 6 2048 98
1 S 178 15 145 37
3 C 3
8 S 179 12 6711 97
5 S 180 26 2335 76
0 S 181 11 6508 38
6 S 182 15 8211 86
0 C 145
5 C 1
9 B 183 38 3124 35
9 B 184 35 9805 66
8 S 185 21 8273 23
9 S 186 39 2963 39
6 C 122
3 S 187 34 4634 43
2 C 134
4 S 188 21 7331 3
2 B 189 48 2400 13
3 B 190 47 3197 13
8 C 121
4 S 191 37 8945 35
9 B 192 39 1613 87
8 C 16
0 C 170
6 B 193 14 1212 99
7 C 111
8 C 28
1 S 194 14 458 28
8 C 96
8 C 36
9 C 186
9 C 183
8 S 195 15 3978 83
7 B 196 20 821 57
6 B 197 0 5429 69
4 C 53
4 B 198 19 1243 35
5 C 1
9 S 199 22 8579 93
3 C 24
3 B 200 15 7405 93
0 C 104
1 C 152
3 B 201 7 475 84
7 C 51
8 C 96
4 S 202 31 5664 57
2 S 203 8 6571 84
4 S 204 11 8118 62
1 C 112
5 C 102
6 S 205 19 8223 85
4 C 53
9 B 206 8 8285 89
6 B 207 33 1152 2
3 B 208 47 5238 40
4 S 209 34 1028 18
0 B 210 27 1385 72
8 S 211 39 7859 8
7 S 212 13 3985 90
7 B 213 40 2362 71
2 B 214 21 1031 34
1 C 112
2 C 23
3 C 3
5 B 215 31 6946 53
0 B 216 30 5388 44
6 B 217 15 5550 26
7 B 218 24 8899 3
2 B 219 32 8054 44
5 S 220 47 6317 37
4 S 221 30 5579 11
2 B 222 24 4349 96
8 B 223 33 301 5
3 C 41
8 B 224 32 1121 61
2 C 173
5 B 225 30 6652 68
4 B 226 3 4381 5
8 C 176
2 C 129
1 C 99
3 B 227 21 7784 20
4 C 90
4 S 228 3 9773 54
5 S 229 25 1895 21
8 C 36
5 B 230 20 253 49
4 C 228
4 B 231 46 784 35
9 C 19
6 C 78
5 B 232 4 3192 77
2 B 233 49 8759 38
8 B 234 27 748 95
3 B 235 30 7392 12
7 S 236 1 8047 97
1 S 237 21 6591 77
1 S 238 42 665 44
9 B 239 45 5936 38
9 B 240 41 8518 41
1 S 241 13 1627 6
0 B 242 29 9297 88
2 S 243 42 3236 5
1 C 55
1 S 244 28 244 6
1 S 245 34 7113 9
5 S 246 19 897 32
8 B 247 4 3948 72
5 C 165
4 S 248 16 3685 26
2 S 249 46 7714 33
7 C 141
9 C 38
2 C 249
2 C 222
2 S 250 35 365 81
4 S 251 18 8914 67
6 S 252 23 5107 95
2 B 253 14 8706 73
7 C 51
0 B 254 45 8891 64
7 S 255 19 247 14
6 C 252
2 S 256 31 6111 94
2 S 257 10 1271 32
4 C 248
5 B 258 40 8534 78
8 S 259 49 246 34
7 C 13
5 C 180
0 C 181
5 B 260 32 3783 50
1 S 261 32 2283 72
3 B 262 48 8091 94
1 C 144
5 C 106
5 C 14
9 C 82
3 B 263 6 9011 88
2 C 142
0 S 264 0 2026 90
4 B 265 29 5979 46
8 B 266 12 4578 27
6 C 217
0 S 267 1 6861 20
0 C 6
5 C 146
3 C 263
6 B 268 14 5783 66
2 B 269 10 5300 45
6 B 270 44 1367 86
6 S 271 13 9567 49
3 B 272 8 2238 85
5 B 273 5 2580 71
4 B 274 18 5244 85
7 C 218
4 S 275 31 4298 42
1 C 244
6 C 268
1 C 152
1 C 194
8 B 276 41 8536 17
7 B 277 26 4509 79
7 B 278 2 4769 76
6 C 154
2 S 279 33 6549 90
2 S 280 21 2535 46
8 C 59
3 S 281 18 7414 63
2 B 282 0 6006 58
8 S 283 27 3774 70
0 C 4
7 C 196
1 C 241
7 B 284 41 9066 25
8 B 285 6 4381 76
3 B 286 10 67 91
4 C 17
5 B 287 20 3890 98
1 C 99
6 B 288 21 8875 87
3 B 289 12 1986 23
0 B 290 24 1426 4
8 B 291 26 7924 21
3 S 292 33 4178 68
1 B 293 17 5782 35
2 C 35
6 C 172
3 C 39
4 B 294 33 3853 75
1 S 295 6 3046 64
1 S 296 22 3104 70
0 S 297 23 8419 73
4 S 298 15 7246 54
6 C 2
1 S 299 4 6804 97
8 C 15
2 C 142
6 B 300 42 9659 58
2 B 301 30 6941 32
5 S 302 34 2803 43
9 B 303 22 1413 61
5 B 304 29 8168 9
9 S 305 1 4153 72
9 S 306 9 4616 74
8 S 307 3 4174 88
0 S 308 19 1366 39
7 S 309 39 7577 17
1 S 310 11 2033 50
2 C 77
3 B 311 49 1325 55
5 S 312 36 6145 90
8 B 313 30 9962 96
8 B 314 13 576 79
1 S 315 4 3425 38
6 C 74
7 B 316 7 6308 29
7 B 317 33 2936 90
3 B 318 42 3510 66
1 C 245
1 S 319 2 9141 17
1 S 320 14 1560 7
1 B 321 15 8946 84
9 C 159
1 B 322 2 6428 98
3 B 323 25 7875 34
7 B 324 39 930 32
3 C 235
5 S 325 40 7787 38
6 B 326 42 6563 99
0 C 267
7 B 327 32 8708 38
7 B 328 16 7791 59
5 C 312
9 S 329 33 7487 48
7 S 330 5 5303 11
9 C 184
6 B 331 33 658 2
5 S 332 0 7982 33
2 S 333 0 554 37
8 B 334 41 193 57
9 S 335 48 9278 43
.
x
