scripts/tests/3.in
20
o
3 S 0 227 9217 45
17 S 1 9 7096 20
2 S 2 160 1998 91
18 B 3 69 333 20
10 B 4 244 5021 93
0 B 5 3 35 12
15 B 6 54 8229 36
19 S 7 200 3578 71
15 C 6
1 B 8 159 1925 78
1 C 8
18 C 3
2 B 9 187 561 67
12 B 10 78 1528 83
8 B 11 40 5994 93
2 B 12 181 9322 43
10 S 13 19 9260 73
13 S 14 207 6913 26
2 C 12
14 B 15 111 8711 61
13 S 16 244 6344 93
8 C 11
6 B 17 243 2279 73
0 C 5
0 B 18 8 7940 46
12 B 19 129 9033 61
12 B 20 72 205 67
3 C 0
6 B 21 200 4222 85
13 S 22 40 1440 20
0 C 18
6 S 23 204 7301 43
6 S 24 18 8442 88
8 C 11
15 B 25 83 107 66
14 C 15
19 B 26 100 1416 10
15 C 25
8 B 27 123 6843 71
13 S 28 184 3483 66
15 S 29 177 8479 16
2 C 9
12 C 10
11 B 30 210 3285 36
0 S 31 60 1512 33
19 B 32 181 8443 75
6 B 33 69 7147 4
15 B 34 127 1410 39
0 B 35 176 954 15
15 S 36 101 2931 86
18 B 37 106 3196 43
1 B 38 168 2116 54
1 B 39 44 120 82
15 S 40 244 5505 61
5 S 41 211 4365 3
14 S 42 201 6220 70
5 C 41
18 B 43 81 9966 26
16 S 44 36 2081 68
1 S 45 210 3752 50
9 B 46 160 8649 91
9 C 46
15 B 47 78 9391 17
13 S 48 118 2388 29
3 B 49 7 4428 87
13 B 50 117 3123 15
9 B 51 133 1703 46
13 C 28
12 S 52 94 6250 82
17 C 1
2 C 9
18 C 43
5 B 53 235 1430 42
11 S 54 49 5111 54
10 C 4
13 C 22
11 S 55 121 4451 17
19 S 56 18 6412 49
13 C 22
2 B 57 224 1324 3
12 C 10
19 B 58 178 8741 53
10 S 59 76 709 44
5 C 53
19 C 58
10 C 59
19 C 32
4 B 60 96 6507 76
12 C 52
6 B 61 156 6039 33
9 C 51
18 S 62 167 2778 77
3 S 63 248 1153 49
8 S 64 61 620 81
3 C 49
15 B 65 224 2213 74
11 S 66 96 9822 82
1 B 67 234 9951 88
0 C 5
18 S 68 14 7267 76
8 C 27
19 C 58
2 S 69 227 4542 57
17 S 70 15 3253 14
12 B 71 73 6567 33
15 C 34
9 S 72 126 8726 22
13 S 73 124 1948 36
1 C 8
5 B 74 159 2279 33
0 S 75 30 914 67
9 C 51
0 S 76 139 6400 24
12 S 77 72 6838 50
12 C 71
17 C 1
0 S 78 115 4706 27
14 S 79 99 5880 71
6 C 33
13 B 80 108 4175 90
2 S 81 68 712 31
5 S 82 188 7810 15
5 S 83 69 2570 7
19 B 84 10 1230 40
5 S 85 87 433 4
8 C 64
18 C 62
18 B 86 33 2448 29
3 B 87 46 9582 48
0 C 76
6 S 88 134 2387 57
8 C 64
19 C 26
9 C 72
19 C 32
5 S 89 87 4062 36
19 S 90 125 4474 17
3 S 91 162 9873 20
12 C 20
12 C 71
0 C 18
3 C 87
2 B 92 122 4114 84
1 B 93 175 811 98
15 C 65
5 B 94 175 1540 95
5 B 95 116 5491 7
19 C 90
9 S 96 41 9050 54
8 C 11
2 S 97 114 704 76
6 S 98 170 8179 15
16 C 44
18 S 99 42 341 43
14 S 100 35 3236 48
5 C 82
17 B 101 189 3158 18
15 C 36
16 C 44
10 S 102 145 850 32
3 S 103 234 4999 78
13 B 104 59 6095 51
17 S 105 13 1245 4
9 C 46
14 C 79
8 S 106 159 3723 12
11 C 30
5 C 82
3 B 107 223 8136 23
2 C 57
13 B 108 38 1211 33
0 S 109 101 9845 54
3 B 110 18 7942 59
0 S 111 81 7636 16
9 S 112 215 7446 60
12 C 52
13 B 113 135 4508 32
16 B 114 156 5037 43
11 S 115 174 400 67
15 B 116 13 5430 67
19 S 117 193 8987 41
4 C 60
19 B 118 181 2719 56
19 S 119 97 290 71
3 S 120 233 7933 85
7 B 121 73 8919 76
3 C 87
16 C 114
1 C 67
11 S 122 179 9265 51
15 B 123 11 1080 69
2 S 124 24 498 50
12 B 125 226 6865 55
9 C 51
8 B 126 215 8580 42
9 C 51
15 B 127 159 6056 50
8 C 126
5 B 128 130 8198 73
9 B 129 48 2341 78
17 S 130 159 451 64
8 C 27
12 S 131 174 6276 96
1 S 132 224 5132 72
1 C 8
11 B 133 88 4709 58
1 B 134 109 1013 90
5 B 135 192 1170 77
16 C 114
10 B 136 232 7689 26
4 C 60
4 B 137 160 6641 81
7 B 138 97 4432 91
9 B 139 15 3426 90
7 C 138
17 C 101
1 C 8
15 B 140 45 447 91
11 S 141 36 8528 90
11 S 142 45 609 30
5 S 143 45 9109 68
6 B 144 244 8660 65
6 S 145 83 3954 14
1 S 146 131 7579 76
9 C 139
14 S 147 30 3937 35
4 S 148 195 7031 73
12 C 10
2 S 149 2 5206 2
8 C 64
4 B 150 77 434 42
16 B 151 166 1936 5
19 B 152 137 4292 99
17 B 153 9 2526 83
8 B 154 53 8835 13
5 C 53
10 C 13
3 S 155 24 7253 3
7 C 138
4 C 60
5 C 74
15 B 156 198 2495 94
8 B 157 178 4004 23
5 S 158 59 9961 14
10 S 159 162 7075 6
15 S 160 217 5721 9
10 S 161 103 6315 5
13 C 14
9 C 72
13 C 50
3 B 162 108 6090 85
17 S 163 54 1823 74
9 S 164 18 4179 30
19 S 165 235 6184 14
2 C 97
7 C 138
5 S 166 121 2505 65
9 B 167 127 124 27
14 C 15
7 S 168 45 2883 87
16 B 169 39 8544 41
17 C 163
7 B 170 117 9403 83
7 B 171 86 1132 82
6 S 172 80 7193 17
2 B 173 232 7875 36
0 C 35
0 B 174 36 6376 7
2 C 149
13 B 175 149 6116 53
18 B 176 162 435 37
19 S 177 146 8433 74
18 B 178 60 7822 19
0 B 179 171 6399 31
19 B 180 37 297 19
12 S 181 171 2693 68
13 B 182 170 6558 58
8 S 183 133 8992 78
16 B 184 241 8023 91
6 B 185 22 8110 73
12 S 186 60 8837 23
1 B 187 168 9788 86
0 S 188 75 1924 86
3 B 189 57 8763 20
18 S 190 176 3409 26
19 C 84
2 B 191 176 3229 19
9 S 192 163 7480 57
3 B 193 102 7758 58
3 B 194 182 5152 34
8 C 64
16 S 195 153 5901 43
0 S 196 183 2440 71
10 S 197 9 7519 67
5 C 85
19 C 177
19 B 198 200 3546 56
18 S 199 77 9761 45
8 C 106
18 S 200 64 7253 90
7 S 201 83 3082 67
3 B 202 166 4104 34
15 S 203 39 1621 44
11 S 204 177 4114 12
5 C 128
15 B 205 42 2355 10
9 S 206 79 6746 70
11 C 55
15 B 207 56 6519 55
1 C 67
4 C 60
9 B 208 31 5396 25
0 S 209 13 3719 61
12 B 210 96 8074 93
11 C 30
7 B 211 207 9136 64
6 B 212 184 5895 79
0 B 213 35 5970 32
17 B 214 140 3701 38
11 B 215 248 3791 2
7 B 216 40 4751 58
17 S 217 217 3708 38
17 B 218 165 8302 82
5 C 143
7 S 219 126 6699 58
0 S 220 53 7390 79
2 B 221 219 6398 39
5 C 85
3 S 222 152 1853 23
1 B 223 136 3418 99
5 B 224 13 1065 96
6 B 225 234 9559 3
5 B 226 69 6727 37
7 S 227 69 6143 89
10 B 228 167 2052 88
5 C 74
0 S 229 143 3910 8
6 C 24
3 B 230 112 4977 47
10 B 231 249 1925 96
19 B 232 185 6137 86
6 B 233 153 502 84
11 B 234 104 5012 81
13 B 235 133 1343 36
7 S 236 45 8514 67
2 C 92
9 C 129
11 B 237 79 3457 47
16 S 238 180 6969 38
18 B 239 55 6849 9
15 B 240 120 4420 19
19 B 241 128 9806 73
19 C 7
19 B 242 92 5871 77
14 S 243 76 3036 26
19 B 244 130 3396 47
12 S 245 37 4210 34
15 B 246 113 5897 2
12 S 247 83 4527 40
2 S 248 210 9191 93
19 B 249 41 9712 75
11 B 250 53 2450 55
14 S 251 87 4732 15
0 S 252 33 1810 10
15 S 253 199 2813 52
10 C 231
7 C 121
7 S 254 39 3776 93
14 B 255 240 5671 35
6 S 256 231 6737 90
1 S 257 129 1635 84
16 C 151
12 C 125
2 S 258 125 4577 19
16 C 151
1 B 259 76 7541 77
0 S 260 51 3678 91
0 B 261 213 5619 66
6 B 262 16 5181 62
7 B 263 166 5773 89
8 B 264 48 4762 62
4 S 265 103 2550 71
16 C 151
6 S 266 93 577 96
8 B 267 33 4609 24
18 C 86
0 B 268 55 2302 29
11 S 269 111 6560 5
3 B 270 12 5457 12
10 B 271 33 1292 2
10 B 272 74 1509 2
7 B 273 210 2520 92
12 C 77
7 C 121
8 C 11
2 S 274 143 416 75
12 C 52
8 C 27
5 B 275 0 1890 65
5 B 276 192 1828 2
5 B 277 19 8460 71
3 S 278 213 3750 35
10 S 279 23 7477 49
12 S 280 61 1571 57
7 S 281 8 5435 26
16 C 44
9 B 282 121 244 62
2 C 258
5 C 226
5 C 95
17 C 153
12 B 283 174 1813 79
14 B 284 180 2284 11
7 S 285 215 3420 69
1 S 286 163 8890 88
0 B 287 180 9125 85
10 C 228
18 S 288 132 3515 71
17 B 289 62 8607 55
6 S 290 151 4514 50
12 B 291 55 7366 27
6 S 292 162 6143 14
18 S 293 27 1733 66
13 B 294 96 2390 81
16 S 295 44 4918 38
9 S 296 192 9 91
13 C 28
18 S 297 54 6946 21
7 B 298 140 2014 75
6 C 212
2 B 299 70 8162 62
13 B 300 127 4539 13
16 C 295
8 B 301 159 6926 62
17 C 153
1 C 132
6 S 302 141 4066 28
5 C 94
18 B 303 131 1277 73
1 S 304 111 6181 51
14 C 255
17 C 70
7 S 305 108 9299 88
12 S 306 239 1224 63
1 C 223
8 B 307 132 4432 43
16 C 114
18 S 308 7 253 26
1 B 309 70 264 5
1 B 310 8 3057 65
13 S 311 131 5190 8
11 C 215
13 S 312 125 2366 21
13 S 313 12 5117 76
17 B 314 58 8626 66
7 C 227
13 S 315 214 3393 7
16 S 316 21 7545 89
18 B 317 156 5297 66
2 B 318 83 9962 41
15 C 205
4 S 319 169 9165 76
17 B 320 175 2139 26
3 B 321 17 6622 26
3 C 321
17 S 322 66 2333 93
2 C 274
12 B 323 49 8863 72
10 S 324 222 8240 5
16 S 325 228 7252 8
14 S 326 57 5533 9
4 B 327 122 4093 99
17 S 328 179 1250 89
10 B 329 56 6866 63
3 C 91
4 S 330 112 2591 93
10 C 197
1 C 310
17 C 101
7 C 168
0 S 331 79 8447 35
13 B 332 199 7322 31
11 S 333 141 3416 11
10 S 334 100 6315 86
13 C 48
17 C 130
17 C 163
11 C 142
0 S 335 230 7496 12
0 S 336 240 9582 91
19 S 337 205 9533 23
6 B 338 51 1157 94
6 S 339 29 823 68
5 C 41
7 B 340 83 486 74
0 S 341 71 1192 67
13 B 342 162 7532 81
13 C 80
14 B 343 0 2567 21
15 S 344 30 7891 67
17 S 345 180 6419 85
19 B 346 91 9574 9
2 S 347 63 2552 72
3 C 202
18 S 348 112 7503 94
